{"name": "pyopenssl", "cve_id": "CVE-2018-1000807", "publish_date": "2018-10-08T15:29Z", "cwe_id": "CWE-400", "owner": "pyca", "affected_versions": [{"version_value": "17.5.0", "operator": "<="}], "references": ["http://lists.opensuse.org/opensuse-security-announce/2019-04/msg00014.html", "https://access.redhat.com/errata/RHSA-2019:0085", "https://github.com/pyca/pyopenssl/pull/723", "https://usn.ubuntu.com/3813-1/", "https://github.com/pyca/pyopenssl/commit/e73818600065821d588af475b024f4eb518c3509"], "description": "Python Cryptographic Authority pyopenssl version prior to version 17.5.0 contains a CWE-416: Use After Free vulnerability in X509 object handling that can result in Use after free can lead to possible denial of service or remote code execution.. This attack appear to be exploitable via Depends on the calling application and if it retains a reference to the memory.. This vulnerability appears to have been fixed in 17.5.0.", "latest_version": "19.0.0", "language": "python", "license": "Apache-2.0", "repository_summary": "Python wrapper module around the OpenSSL library", "repo_url": "https://github.com/pyca/pyopenssl", "impact": {"cvss2_score": 4.3, "cvss2_severity": "MEDIUM", "vector_string": "CVSS:3.0/AV:N/AC:H/PR:N/UI:N/S:U/C:N/I:N/A:H", "av": "NETWORK", "ac": "HIGH", "pr": "NONE", "c": "NONE", "i": "NONE", "a": "HIGH", "impact_score": 3.6, "exploitability_score": 2.2, "cvss3_score": 5.9, "cvss3_severity": "MEDIUM", "ui": "NONE", "s": "UNCHANGED"}, "ochrona_severity_score": 5.9}