{"name": "validators", "cve_id": "CVE-2019-19588", "publish_date": "2019-12-05T01:15Z", "cwe_id": "CWE-835", "owner": "Konsta Vesterinen", "affected_versions": [{"version_value": "0.12.2", "operator": "="}, {"version_value": "0.12.3", "operator": "="}, {"version_value": "0.12.4", "operator": "="}, {"version_value": "0.12.5", "operator": "="}], "references": ["https://github.com/kvesteri/validators/issues/86"], "description": "The validators package 0.12.2 through 0.12.5 for Python enters an infinite loop when validators.domain is called with a crafted domain string. This is fixed in 0.12.6.", "latest_version": "0.18.1", "language": "python", "license": "MIT", "repository_summary": "Python Data Validation for Humans\u2122.", "repo_url": "https://github.com/kvesteri/validators", "impact": {"cvss2_score": 7.8, "cvss2_severity": "HIGH", "vector_string": "CVSS:3.1/AV:N/AC:L/PR:N/UI:N/S:U/C:N/I:N/A:H", "av": "NETWORK", "ac": "LOW", "pr": "NONE", "c": "NONE", "i": "NONE", "a": "HIGH", "impact_score": 3.6, "exploitability_score": 3.9, "cvss3_score": 7.5, "cvss3_severity": "HIGH", "ui": "NONE", "s": "UNCHANGED"}, "ochrona_severity_score": 7.5}